2024-03-21 09:50:48,212 INFO    MainThread:799 [wandb_setup.py:_flush():76] Current SDK version is 0.16.3
2024-03-21 09:50:48,213 INFO    MainThread:799 [wandb_setup.py:_flush():76] Configure stats pid to 799
2024-03-21 09:50:48,214 INFO    MainThread:799 [wandb_setup.py:_flush():76] Loading settings from /home/souvik/.config/wandb/settings
2024-03-21 09:50:48,214 INFO    MainThread:799 [wandb_setup.py:_flush():76] Loading settings from /mnt/d/WSL/Flight-Fare-Prediction/wandb/settings
2024-03-21 09:50:48,214 INFO    MainThread:799 [wandb_setup.py:_flush():76] Loading settings from environment variables: {}
2024-03-21 09:50:48,214 INFO    MainThread:799 [wandb_setup.py:_flush():76] Inferring run settings from compute environment: {'program': '<python with no main file>'}
2024-03-21 09:50:48,215 INFO    MainThread:799 [wandb_init.py:_log_setup():526] Logging user logs to /mnt/d/WSL/Flight-Fare-Prediction/wandb/run-20240321_095048-Info/logs/debug.log
2024-03-21 09:50:48,216 INFO    MainThread:799 [wandb_init.py:_log_setup():527] Logging internal logs to /mnt/d/WSL/Flight-Fare-Prediction/wandb/run-20240321_095048-Info/logs/debug-internal.log
2024-03-21 09:50:48,216 INFO    MainThread:799 [wandb_init.py:init():566] calling init triggers
2024-03-21 09:50:48,216 INFO    MainThread:799 [wandb_init.py:init():573] wandb.init called with sweep_config: {}
config: {}
2024-03-21 09:50:48,217 INFO    MainThread:799 [wandb_init.py:init():591] re-initializing run, found existing run on stack: k6diig4z
2024-03-21 09:50:48,219 INFO    MainThread:799 [wandb_run.py:_finish():1970] finishing run ghsouvikprof/Flight Fare/k6diig4z
2024-03-21 09:50:48,220 ERROR   MainThread:799 [jupyter.py:save_history():437] Run pip install nbformat to save notebook history
2024-03-21 09:50:48,220 INFO    MainThread:799 [jupyter.py:save_ipynb():373] not saving jupyter notebook
2024-03-21 09:50:48,220 INFO    MainThread:799 [wandb_init.py:_jupyter_teardown():454] cleaning up jupyter logic
2024-03-21 09:50:48,221 INFO    MainThread:799 [wandb_run.py:_atexit_cleanup():2210] got exitcode: 0
2024-03-21 09:50:48,221 INFO    MainThread:799 [wandb_run.py:_restore():2193] restore
2024-03-21 09:50:48,222 INFO    MainThread:799 [wandb_run.py:_restore():2199] restore done
2024-03-21 09:50:54,313 INFO    MainThread:799 [wandb_run.py:_footer_history_summary_info():3866] rendering history
2024-03-21 09:50:54,314 INFO    MainThread:799 [wandb_run.py:_footer_history_summary_info():3898] rendering summary
2024-03-21 09:50:54,319 INFO    MainThread:799 [wandb_run.py:_footer_sync_info():3825] logging synced files
2024-03-21 09:50:55,399 INFO    MainThread:799 [wandb_init.py:init():616] starting backend
2024-03-21 09:50:55,400 INFO    MainThread:799 [wandb_init.py:init():620] setting up manager
2024-03-21 09:50:55,402 INFO    MainThread:799 [backend.py:_multiprocessing_setup():105] multiprocessing start_methods=fork,spawn,forkserver, using: spawn
2024-03-21 09:50:55,403 INFO    MainThread:799 [wandb_init.py:init():628] backend started and connected
2024-03-21 09:50:55,410 INFO    MainThread:799 [wandb_run.py:_label_probe_notebook():1295] probe notebook
2024-03-21 09:50:55,411 INFO    MainThread:799 [wandb_run.py:_label_probe_notebook():1305] Unable to probe notebook: 'NoneType' object has no attribute 'get'
2024-03-21 09:50:55,411 INFO    MainThread:799 [wandb_init.py:init():720] updated telemetry
2024-03-21 09:50:55,468 INFO    MainThread:799 [wandb_init.py:init():753] communicating run to backend with 90.0 second timeout
2024-03-21 09:50:57,574 INFO    MainThread:799 [wandb_run.py:_on_init():2262] communicating current version
2024-03-21 09:50:59,783 INFO    MainThread:799 [wandb_run.py:_on_init():2271] got version response upgrade_message: "wandb version 0.16.4 is available!  To upgrade, please run:\n $ pip install wandb --upgrade"

2024-03-21 09:50:59,784 INFO    MainThread:799 [wandb_init.py:init():804] starting run threads in backend
2024-03-21 09:51:03,629 INFO    MainThread:799 [wandb_run.py:_console_start():2241] atexit reg
2024-03-21 09:51:03,630 INFO    MainThread:799 [wandb_run.py:_redirect():2096] redirect: wrap_raw
2024-03-21 09:51:03,630 INFO    MainThread:799 [wandb_run.py:_redirect():2161] Wrapping output streams.
2024-03-21 09:51:03,630 INFO    MainThread:799 [wandb_run.py:_redirect():2186] Redirects installed.
2024-03-21 09:51:03,631 INFO    MainThread:799 [wandb_init.py:init():847] run started, returning control to user process
2024-03-21 09:54:48,257 ERROR   MainThread:799 [util.py:get_module():267] Error importing optional module plotly.tools
Traceback (most recent call last):
  File "/home/souvik/miniconda3/lib/python3.11/site-packages/wandb/util.py", line 233, in import_module_lazy
    return sys.modules[name]
           ~~~~~~~~~~~^^^^^^
KeyError: 'plotly.tools'

During handling of the above exception, another exception occurred:

Traceback (most recent call last):
  File "/home/souvik/miniconda3/lib/python3.11/site-packages/wandb/util.py", line 262, in get_module
    return import_module_lazy(name)
           ^^^^^^^^^^^^^^^^^^^^^^^^
  File "/home/souvik/miniconda3/lib/python3.11/site-packages/wandb/util.py", line 235, in import_module_lazy
    spec = importlib.util.find_spec(name)
           ^^^^^^^^^^^^^^^^^^^^^^^^^^^^^^
  File "<frozen importlib.util>", line 94, in find_spec
ModuleNotFoundError: No module named 'plotly'
