2024-03-20 18:59:10,361 INFO    MainThread:766 [wandb_setup.py:_flush():76] Current SDK version is 0.16.3
2024-03-20 18:59:10,361 INFO    MainThread:766 [wandb_setup.py:_flush():76] Configure stats pid to 766
2024-03-20 18:59:10,362 INFO    MainThread:766 [wandb_setup.py:_flush():76] Loading settings from /home/souvik/.config/wandb/settings
2024-03-20 18:59:10,362 INFO    MainThread:766 [wandb_setup.py:_flush():76] Loading settings from /mnt/d/WSL/Flight-Fare-Prediction/wandb/settings
2024-03-20 18:59:10,362 INFO    MainThread:766 [wandb_setup.py:_flush():76] Loading settings from environment variables: {}
2024-03-20 18:59:10,363 INFO    MainThread:766 [wandb_setup.py:_flush():76] Inferring run settings from compute environment: {'program': '<python with no main file>'}
2024-03-20 18:59:10,364 INFO    MainThread:766 [wandb_init.py:_log_setup():526] Logging user logs to /mnt/d/WSL/Flight-Fare-Prediction/wandb/run-20240320_185910-7ruczazo/logs/debug.log
2024-03-20 18:59:10,364 INFO    MainThread:766 [wandb_init.py:_log_setup():527] Logging internal logs to /mnt/d/WSL/Flight-Fare-Prediction/wandb/run-20240320_185910-7ruczazo/logs/debug-internal.log
2024-03-20 18:59:10,365 INFO    MainThread:766 [wandb_init.py:init():566] calling init triggers
2024-03-20 18:59:10,365 INFO    MainThread:766 [wandb_init.py:init():573] wandb.init called with sweep_config: {}
config: {}
2024-03-20 18:59:10,365 INFO    MainThread:766 [wandb_init.py:init():616] starting backend
2024-03-20 18:59:10,365 INFO    MainThread:766 [wandb_init.py:init():620] setting up manager
2024-03-20 18:59:10,372 INFO    MainThread:766 [backend.py:_multiprocessing_setup():105] multiprocessing start_methods=fork,spawn,forkserver, using: spawn
2024-03-20 18:59:10,373 INFO    MainThread:766 [wandb_init.py:init():628] backend started and connected
2024-03-20 18:59:10,386 INFO    MainThread:766 [wandb_run.py:_label_probe_notebook():1295] probe notebook
2024-03-20 18:59:10,386 INFO    MainThread:766 [wandb_run.py:_label_probe_notebook():1305] Unable to probe notebook: 'NoneType' object has no attribute 'get'
2024-03-20 18:59:10,386 INFO    MainThread:766 [wandb_init.py:init():720] updated telemetry
2024-03-20 18:59:10,469 INFO    MainThread:766 [wandb_init.py:init():753] communicating run to backend with 90.0 second timeout
2024-03-20 18:59:47,281 WARNING MainThread:766 [wandb_init.py:init():1198] interrupted
Traceback (most recent call last):
  File "/home/souvik/miniconda3/lib/python3.11/site-packages/wandb/sdk/wandb_init.py", line 1176, in init
    run = wi.init()
          ^^^^^^^^^
  File "/home/souvik/miniconda3/lib/python3.11/site-packages/wandb/sdk/wandb_init.py", line 756, in init
    result = run_init_handle.wait(
             ^^^^^^^^^^^^^^^^^^^^^
  File "/home/souvik/miniconda3/lib/python3.11/site-packages/wandb/sdk/lib/mailbox.py", line 283, in wait
    found, abandoned = self._slot._get_and_clear(timeout=wait_timeout)
                       ^^^^^^^^^^^^^^^^^^^^^^^^^^^^^^^^^^^^^^^^^^^^^^^
  File "/home/souvik/miniconda3/lib/python3.11/site-packages/wandb/sdk/lib/mailbox.py", line 130, in _get_and_clear
    if self._wait(timeout=timeout):
       ^^^^^^^^^^^^^^^^^^^^^^^^^^^
  File "/home/souvik/miniconda3/lib/python3.11/site-packages/wandb/sdk/lib/mailbox.py", line 126, in _wait
    return self._event.wait(timeout=timeout)
           ^^^^^^^^^^^^^^^^^^^^^^^^^^^^^^^^^
  File "/home/souvik/miniconda3/lib/python3.11/threading.py", line 622, in wait
    signaled = self._cond.wait(timeout)
               ^^^^^^^^^^^^^^^^^^^^^^^^
  File "/home/souvik/miniconda3/lib/python3.11/threading.py", line 324, in wait
    gotit = waiter.acquire(True, timeout)
            ^^^^^^^^^^^^^^^^^^^^^^^^^^^^^
KeyboardInterrupt
2024-03-20 18:59:58,664 INFO    MainThread:766 [wandb_setup.py:_flush():76] Current SDK version is 0.16.3
2024-03-20 18:59:58,664 INFO    MainThread:766 [wandb_setup.py:_flush():76] Configure stats pid to 766
2024-03-20 18:59:58,665 INFO    MainThread:766 [wandb_setup.py:_flush():76] Loading settings from /home/souvik/.config/wandb/settings
2024-03-20 18:59:58,665 INFO    MainThread:766 [wandb_setup.py:_flush():76] Loading settings from /mnt/d/WSL/Flight-Fare-Prediction/wandb/settings
2024-03-20 18:59:58,666 INFO    MainThread:766 [wandb_setup.py:_flush():76] Loading settings from environment variables: {}
2024-03-20 18:59:58,666 INFO    MainThread:766 [wandb_setup.py:_flush():76] Inferring run settings from compute environment: {'program': '<python with no main file>'}
2024-03-20 18:59:58,667 INFO    MainThread:766 [wandb_init.py:_log_setup():526] Logging user logs to /mnt/d/WSL/Flight-Fare-Prediction/wandb/run-20240320_185958-hdwxbxdg/logs/debug.log
2024-03-20 18:59:58,668 INFO    MainThread:766 [wandb_init.py:_log_setup():527] Logging internal logs to /mnt/d/WSL/Flight-Fare-Prediction/wandb/run-20240320_185958-hdwxbxdg/logs/debug-internal.log
2024-03-20 18:59:58,668 INFO    MainThread:766 [wandb_init.py:init():566] calling init triggers
2024-03-20 18:59:58,669 INFO    MainThread:766 [wandb_init.py:init():573] wandb.init called with sweep_config: {}
config: {}
2024-03-20 18:59:58,669 INFO    MainThread:766 [wandb_init.py:init():616] starting backend
2024-03-20 18:59:58,670 INFO    MainThread:766 [wandb_init.py:init():620] setting up manager
2024-03-20 18:59:58,676 INFO    MainThread:766 [backend.py:_multiprocessing_setup():105] multiprocessing start_methods=fork,spawn,forkserver, using: spawn
2024-03-20 18:59:58,677 INFO    MainThread:766 [wandb_init.py:init():628] backend started and connected
2024-03-20 18:59:58,689 INFO    MainThread:766 [wandb_run.py:_label_probe_notebook():1295] probe notebook
2024-03-20 18:59:58,690 INFO    MainThread:766 [wandb_run.py:_label_probe_notebook():1305] Unable to probe notebook: 'NoneType' object has no attribute 'get'
2024-03-20 18:59:58,692 INFO    MainThread:766 [wandb_init.py:init():720] updated telemetry
2024-03-20 18:59:58,749 INFO    MainThread:766 [wandb_init.py:init():753] communicating run to backend with 90.0 second timeout
2024-03-20 18:59:59,319 ERROR   MainThread:766 [wandb_init.py:init():779] encountered error: It appears that you do not have permission to access the requested resource. Please reach out to the project owner to grant you access. If you have the correct permissions, verify that there are no issues with your networking setup.(Error 403: Forbidden)
2024-03-20 18:59:59,444 ERROR   MainThread:766 [wandb_init.py:init():1194] It appears that you do not have permission to access the requested resource. Please reach out to the project owner to grant you access. If you have the correct permissions, verify that there are no issues with your networking setup.(Error 403: Forbidden)
Traceback (most recent call last):
  File "/home/souvik/miniconda3/lib/python3.11/site-packages/wandb/sdk/wandb_init.py", line 1176, in init
    run = wi.init()
          ^^^^^^^^^
  File "/home/souvik/miniconda3/lib/python3.11/site-packages/wandb/sdk/wandb_init.py", line 785, in init
    raise error
wandb.errors.CommError: It appears that you do not have permission to access the requested resource. Please reach out to the project owner to grant you access. If you have the correct permissions, verify that there are no issues with your networking setup.(Error 403: Forbidden)
2024-03-20 19:01:27,446 INFO    MainThread:766 [wandb_setup.py:_flush():76] Current SDK version is 0.16.3
2024-03-20 19:01:27,447 INFO    MainThread:766 [wandb_setup.py:_flush():76] Configure stats pid to 766
2024-03-20 19:01:27,447 INFO    MainThread:766 [wandb_setup.py:_flush():76] Loading settings from /home/souvik/.config/wandb/settings
2024-03-20 19:01:27,448 INFO    MainThread:766 [wandb_setup.py:_flush():76] Loading settings from /mnt/d/WSL/Flight-Fare-Prediction/wandb/settings
2024-03-20 19:01:27,448 INFO    MainThread:766 [wandb_setup.py:_flush():76] Loading settings from environment variables: {}
2024-03-20 19:01:27,449 INFO    MainThread:766 [wandb_setup.py:_flush():76] Inferring run settings from compute environment: {'program': '<python with no main file>'}
2024-03-20 19:01:27,450 INFO    MainThread:766 [wandb_init.py:_log_setup():526] Logging user logs to /mnt/d/WSL/Flight-Fare-Prediction/wandb/run-20240320_190127-dataset/logs/debug.log
2024-03-20 19:01:27,451 INFO    MainThread:766 [wandb_init.py:_log_setup():527] Logging internal logs to /mnt/d/WSL/Flight-Fare-Prediction/wandb/run-20240320_190127-dataset/logs/debug-internal.log
2024-03-20 19:01:27,451 INFO    MainThread:766 [wandb_init.py:init():566] calling init triggers
2024-03-20 19:01:27,452 INFO    MainThread:766 [wandb_init.py:init():573] wandb.init called with sweep_config: {}
config: {}
2024-03-20 19:01:27,453 INFO    MainThread:766 [wandb_init.py:init():616] starting backend
2024-03-20 19:01:27,454 INFO    MainThread:766 [wandb_init.py:init():620] setting up manager
2024-03-20 19:01:27,482 INFO    MainThread:766 [backend.py:_multiprocessing_setup():105] multiprocessing start_methods=fork,spawn,forkserver, using: spawn
2024-03-20 19:01:27,490 INFO    MainThread:766 [wandb_init.py:init():628] backend started and connected
2024-03-20 19:01:27,504 INFO    MainThread:766 [wandb_run.py:_label_probe_notebook():1295] probe notebook
2024-03-20 19:01:27,505 INFO    MainThread:766 [wandb_run.py:_label_probe_notebook():1305] Unable to probe notebook: 'NoneType' object has no attribute 'get'
2024-03-20 19:01:27,506 INFO    MainThread:766 [wandb_init.py:init():720] updated telemetry
2024-03-20 19:01:27,584 INFO    MainThread:766 [wandb_init.py:init():753] communicating run to backend with 90.0 second timeout
2024-03-20 19:02:57,607 ERROR   MainThread:766 [wandb_init.py:init():779] encountered error: Run initialization has timed out after 90.0 sec. 
Please refer to the documentation for additional information: https://docs.wandb.ai/guides/track/tracking-faq#initstarterror-error-communicating-with-wandb-process-
2024-03-20 19:02:57,753 ERROR   MainThread:766 [wandb_init.py:init():1194] Run initialization has timed out after 90.0 sec. 
Please refer to the documentation for additional information: https://docs.wandb.ai/guides/track/tracking-faq#initstarterror-error-communicating-with-wandb-process-
Traceback (most recent call last):
  File "/home/souvik/miniconda3/lib/python3.11/site-packages/wandb/sdk/wandb_init.py", line 1176, in init
    run = wi.init()
          ^^^^^^^^^
  File "/home/souvik/miniconda3/lib/python3.11/site-packages/wandb/sdk/wandb_init.py", line 785, in init
    raise error
wandb.errors.CommError: Run initialization has timed out after 90.0 sec. 
Please refer to the documentation for additional information: https://docs.wandb.ai/guides/track/tracking-faq#initstarterror-error-communicating-with-wandb-process-
